2024-04-13 17:44:37,670 INFO    MainThread:86551 [wandb_setup.py:_flush():76] Current SDK version is 0.16.6
2024-04-13 17:44:37,670 INFO    MainThread:86551 [wandb_setup.py:_flush():76] Configure stats pid to 86551
2024-04-13 17:44:37,670 INFO    MainThread:86551 [wandb_setup.py:_flush():76] Loading settings from /home/raid/.config/wandb/settings
2024-04-13 17:44:37,670 INFO    MainThread:86551 [wandb_setup.py:_flush():76] Loading settings from /home/raid/Desktop/Akhil/AirSim-PyTorch-Drone-DDQN-Agent/wandb/settings
2024-04-13 17:44:37,670 INFO    MainThread:86551 [wandb_setup.py:_flush():76] Loading settings from environment variables: {}
2024-04-13 17:44:37,670 INFO    MainThread:86551 [wandb_setup.py:_flush():76] Applying setup settings: {'_disable_service': False}
2024-04-13 17:44:37,670 INFO    MainThread:86551 [wandb_setup.py:_flush():76] Inferring run settings from compute environment: {'program_relpath': 'run.py', 'program_abspath': '/home/raid/Desktop/Akhil/AirSim-PyTorch-Drone-DDQN-Agent/run.py', 'program': '/home/raid/Desktop/Akhil/AirSim-PyTorch-Drone-DDQN-Agent/run.py'}
2024-04-13 17:44:37,670 INFO    MainThread:86551 [wandb_setup.py:_flush():76] Applying login settings: {}
2024-04-13 17:44:37,670 INFO    MainThread:86551 [wandb_init.py:_log_setup():521] Logging user logs to /home/raid/Desktop/Akhil/AirSim-PyTorch-Drone-DDQN-Agent/wandb/run-20240413_174437-aa29tckq/logs/debug.log
2024-04-13 17:44:37,671 INFO    MainThread:86551 [wandb_init.py:_log_setup():522] Logging internal logs to /home/raid/Desktop/Akhil/AirSim-PyTorch-Drone-DDQN-Agent/wandb/run-20240413_174437-aa29tckq/logs/debug-internal.log
2024-04-13 17:44:37,671 INFO    MainThread:86551 [wandb_init.py:init():561] calling init triggers
2024-04-13 17:44:37,671 INFO    MainThread:86551 [wandb_init.py:init():568] wandb.init called with sweep_config: {}
config: {}
2024-04-13 17:44:37,671 INFO    MainThread:86551 [wandb_init.py:init():611] starting backend
2024-04-13 17:44:37,671 INFO    MainThread:86551 [wandb_init.py:init():615] setting up manager
2024-04-13 17:44:37,673 INFO    MainThread:86551 [backend.py:_multiprocessing_setup():105] multiprocessing start_methods=fork,spawn,forkserver, using: spawn
2024-04-13 17:44:37,674 INFO    MainThread:86551 [wandb_init.py:init():623] backend started and connected
2024-04-13 17:44:37,676 INFO    MainThread:86551 [wandb_init.py:init():715] updated telemetry
2024-04-13 17:44:37,693 INFO    MainThread:86551 [wandb_init.py:init():748] communicating run to backend with 90.0 second timeout
2024-04-13 17:45:16,272 INFO    Thread-2  :86551 [retry.py:__call__():172] Retry attempt failed:
Traceback (most recent call last):
  File "/home/raid/miniconda3/envs/airsim_env/lib/python3.9/site-packages/urllib3/connection.py", line 198, in _new_conn
    sock = connection.create_connection(
  File "/home/raid/miniconda3/envs/airsim_env/lib/python3.9/site-packages/urllib3/util/connection.py", line 60, in create_connection
    for res in socket.getaddrinfo(host, port, family, socket.SOCK_STREAM):
  File "/home/raid/miniconda3/envs/airsim_env/lib/python3.9/socket.py", line 954, in getaddrinfo
    for res in _socket.getaddrinfo(host, port, family, type, proto, flags):
socket.gaierror: [Errno -3] Temporary failure in name resolution

The above exception was the direct cause of the following exception:

Traceback (most recent call last):
  File "/home/raid/miniconda3/envs/airsim_env/lib/python3.9/site-packages/urllib3/connectionpool.py", line 793, in urlopen
    response = self._make_request(
  File "/home/raid/miniconda3/envs/airsim_env/lib/python3.9/site-packages/urllib3/connectionpool.py", line 491, in _make_request
    raise new_e
  File "/home/raid/miniconda3/envs/airsim_env/lib/python3.9/site-packages/urllib3/connectionpool.py", line 467, in _make_request
    self._validate_conn(conn)
  File "/home/raid/miniconda3/envs/airsim_env/lib/python3.9/site-packages/urllib3/connectionpool.py", line 1099, in _validate_conn
    conn.connect()
  File "/home/raid/miniconda3/envs/airsim_env/lib/python3.9/site-packages/urllib3/connection.py", line 616, in connect
    self.sock = sock = self._new_conn()
  File "/home/raid/miniconda3/envs/airsim_env/lib/python3.9/site-packages/urllib3/connection.py", line 205, in _new_conn
    raise NameResolutionError(self.host, self, e) from e
urllib3.exceptions.NameResolutionError: <urllib3.connection.HTTPSConnection object at 0x7f41127da850>: Failed to resolve 'api.wandb.ai' ([Errno -3] Temporary failure in name resolution)

The above exception was the direct cause of the following exception:

Traceback (most recent call last):
  File "/home/raid/miniconda3/envs/airsim_env/lib/python3.9/site-packages/requests/adapters.py", line 486, in send
    resp = conn.urlopen(
  File "/home/raid/miniconda3/envs/airsim_env/lib/python3.9/site-packages/urllib3/connectionpool.py", line 847, in urlopen
    retries = retries.increment(
  File "/home/raid/miniconda3/envs/airsim_env/lib/python3.9/site-packages/urllib3/util/retry.py", line 515, in increment
    raise MaxRetryError(_pool, url, reason) from reason  # type: ignore[arg-type]
urllib3.exceptions.MaxRetryError: HTTPSConnectionPool(host='api.wandb.ai', port=443): Max retries exceeded with url: /graphql (Caused by NameResolutionError("<urllib3.connection.HTTPSConnection object at 0x7f41127da850>: Failed to resolve 'api.wandb.ai' ([Errno -3] Temporary failure in name resolution)"))

During handling of the above exception, another exception occurred:

Traceback (most recent call last):
  File "/home/raid/miniconda3/envs/airsim_env/lib/python3.9/site-packages/wandb/sdk/lib/retry.py", line 131, in __call__
    result = self._call_fn(*args, **kwargs)
  File "/home/raid/miniconda3/envs/airsim_env/lib/python3.9/site-packages/wandb/sdk/internal/internal_api.py", line 369, in execute
    return self.client.execute(*args, **kwargs)  # type: ignore
  File "/home/raid/miniconda3/envs/airsim_env/lib/python3.9/site-packages/wandb/vendor/gql-0.2.0/wandb_gql/client.py", line 52, in execute
    result = self._get_result(document, *args, **kwargs)
  File "/home/raid/miniconda3/envs/airsim_env/lib/python3.9/site-packages/wandb/vendor/gql-0.2.0/wandb_gql/client.py", line 60, in _get_result
    return self.transport.execute(document, *args, **kwargs)
  File "/home/raid/miniconda3/envs/airsim_env/lib/python3.9/site-packages/wandb/sdk/lib/gql_request.py", line 58, in execute
    request = self.session.post(self.url, **post_args)
  File "/home/raid/miniconda3/envs/airsim_env/lib/python3.9/site-packages/requests/sessions.py", line 637, in post
    return self.request("POST", url, data=data, json=json, **kwargs)
  File "/home/raid/miniconda3/envs/airsim_env/lib/python3.9/site-packages/requests/sessions.py", line 589, in request
    resp = self.send(prep, **send_kwargs)
  File "/home/raid/miniconda3/envs/airsim_env/lib/python3.9/site-packages/requests/sessions.py", line 703, in send
    r = adapter.send(request, **kwargs)
  File "/home/raid/miniconda3/envs/airsim_env/lib/python3.9/site-packages/requests/adapters.py", line 519, in send
    raise ConnectionError(e, request=request)
requests.exceptions.ConnectionError: HTTPSConnectionPool(host='api.wandb.ai', port=443): Max retries exceeded with url: /graphql (Caused by NameResolutionError("<urllib3.connection.HTTPSConnection object at 0x7f41127da850>: Failed to resolve 'api.wandb.ai' ([Errno -3] Temporary failure in name resolution)"))
2024-04-13 17:46:07,712 ERROR   MainThread:86551 [wandb_init.py:init():774] encountered error: Run initialization has timed out after 90.0 sec. 
Please refer to the documentation for additional information: https://docs.wandb.ai/guides/track/tracking-faq#initstarterror-error-communicating-with-wandb-process-
2024-04-13 17:46:09,719 ERROR   MainThread:86551 [wandb_init.py:init():1199] Run initialization has timed out after 90.0 sec. 
Please refer to the documentation for additional information: https://docs.wandb.ai/guides/track/tracking-faq#initstarterror-error-communicating-with-wandb-process-
Traceback (most recent call last):
  File "/home/raid/miniconda3/envs/airsim_env/lib/python3.9/site-packages/wandb/sdk/wandb_init.py", line 1181, in init
    run = wi.init()
  File "/home/raid/miniconda3/envs/airsim_env/lib/python3.9/site-packages/wandb/sdk/wandb_init.py", line 780, in init
    raise error
wandb.errors.CommError: Run initialization has timed out after 90.0 sec. 
Please refer to the documentation for additional information: https://docs.wandb.ai/guides/track/tracking-faq#initstarterror-error-communicating-with-wandb-process-
2024-04-13 17:46:12,715 WARNING MsgRouterThr:86551 [router.py:message_loop():77] message_loop has been closed
